Workbook
Name calibrators: calibratorsdb[Name]
Name calibrators: [1]!calibratorsdb[Name]
Name calibrators: calibratorsdb[Name]
Name LoadCell: Table1[Description]
Name LoadCell: Table1[Description]
Name LoadCell: [1]!Table1[Description]
Name LoadCell: Table1[Description]
Name LoadCelldb: Table1[]
Name LoadCelldb: Table1[]
Name LoadCelldb: [1]!Table1[#Data]
Name LoadCelldb: Table1[]
Name sadasda: [2]!TypesMachinedb[#Data]
Name TypesMachine: #REF!
Name TypesMachine: #REF!
Name TypesMachine: [1]!TypesMachinedb3[#Data]
Name TypesMachine: TypesMachinedb3[Types of Machine]

Sheet Dash Board
X3: Equipment Photo: | Z3: Photo 1
B7: Name/Company : | D7: SAVVICE CORPORATION | K7: Place of Calibration : | N7: Force Standards Laboratory, NML ITDI | S7: Machine Indication
B8: Address Line 1 : | D8: 3rd Floor BMWC Bldg., Cagayan Valley Road | S8: 0 | T8: 0
B9: Address Line 2 : | D9: Sta. Rita, Guiginto, Bulacan | K9: Person in Charge : | S9: 1st | T9: 3000
B10: Requesting Official : | D10: Ramil F. De Luna | K10: Analyst/Calibrator : | N10: Ahdrian Camilo C. Gernale | S10: 2nd | T10: 6000
B11: Position : | D11: Technician | N11: Radley F. Manalo | S11: 3rd | T11: 9000
S12: 4th | T12: 12000
S13: 5th | T13: 15000
S14: 6th
S15: 7th | Z15: Photo 2
S16: 8th
B17: Date of Calibration : | D17: 46134 | K17: Calibration Mode | N17: Compression | S17: 9th
B18: Req. Reference No. : | D18: 03-2026-FORC-0087 | K18: Capacity : | N18: 15000 | O18: kgf | S18: 10th
B19: Calibration Item : | D19: Axle Weighing Scale | K19: Range : | N19: 0 | O19: =" "&O18&" to " -> kgf to | P19: 15000 | Q19: =O18 -> kgf | S19: 0 | T19: 0
B20: Calibration Type : | K20: Increment | M20: : | N20: 50 | O20: =Q19 -> kgf
B21: Load Cell Type : | D21: No | K21: Resolution : | N21: 50 | O21: =Q19 -> kgf
B22: Force Transducer Info
B23: Make / Model No. : | D23: LS 630 W. PAD
B24: Serial No. / ID No. : | D24: 0122YL21002
B25: Indicator Info
B26: Make / Model No. : | D26: INTERCOMP PT20
B27: Serial No. / ID No. : | D27: 0307YM23003
B29: Special Instructions & Remarks :
G31: please input above the preparations and other pertinent details for the calibrators to remember before starting
B32: Calibrator Tools :
B38: TSR # | D38: Date of Calibration | F38: In-Charge/ Supervisor | H38: Location | J38: Standards Used | K38: Calibrator/ Analyst | M38: Test Points | X38: Equivalent Force | AI38: U | AJ38: Class | AK38: Remarks
M39: 1st | N39: 2nd | O39: 3rd | P39: 4th | Q39: 5th | R39: 6th | S39: 7th | T39: 8th | U39: 9th | V39: 10th | X39: 1st | Y39: 2nd | Z39: 3rd | AA39: 4th | AB39: 5th | AC39: 6th | AD39: 7th | AE39: 8th | AF39: 9th | AG39: 10th

Sheet Software
A1: FORCE MEASUREMENT DATA
A2: Ver. 2 Rev.0 Mar 12, 2019
A3: revised & developed by: gearnhale@yahoo.com according to ISO
A4: original developer: manuelmruiz@yahoo.com
A5: =IF(NOW()>G40,"Calibration of Standard Expired - DO NOT USE!","") -> Calibration of Standard Expired - DO NOT USE!
A6: Date of Calibration | B6: ='Dash Board'!D17 -> 46134 | C6: Calibration Mode | F6: ='Dash Board'!N17 -> Compression
A7: Request Reference No. | B7: ='Dash Board'!D18 -> 03-2026-FORC-0087 | C7: Capacity | F7: ='Dash Board'!N18 -> 15000
A8: Calibration Item | B8: ='Dash Board'!D19 -> Axle Weighing Scale | C8: Range | F8: ='Dash Board'!N19&'Dash Board'!O19&'Dash Board'!P19&" "&'Dash Board'!Q19 -> 0 kgf to 15000 kgf
A9: Make / Model No. | B9: ='Dash Board'!D23 -> LS 630 W. PAD | C9: Increment/Graduation | F9: ='Dash Board'!N20&" "&'Dash Board'!O20 -> 50 kgf
A10: Serial No. / ID No. | B10: ='Dash Board'!D24 -> 0122YL21002 | C10: Resolution | F10: ='Dash Board'!N21&" "&'Dash Board'!O21 -> 50 kgf
A12: Guide on how to use this data entry system: | D12: Environmental Conditions:
A13: 1. Select the radio button of the machine indicator unit (kgf, lbf, N, kN). | E13: Before | F13: After
A14: 2. After capturing the digital amplifier's reading, change the machine indication accordingly. | D14: Temp: | E14: 25 | F14: 25
A15: 3. Upon completion of each loading set, press the corresponding PRINT button. Make sure you have | D15: Humidity: | E15: 33 | F15: 33
A16: change first the machine indication reading upon capturing.
A17: Data Logger | D17: Calibration Worksheet
I18: Machine Indicator Readability | K18: =F10 -> 50 kgf
A19: Zero | B19: 1.1 1.1-DMP40 0.078086 mV/V abs 13-Mar-19 13:04:56
B20: Excitation: 5.0 V Meas. Range: 2.5 mV/V | D20: Test | E20: Machine Indication | I20: Load Cell Indication, mV/V | K20: Equivalent Force, kN | M20: =" : Pre-load from 0 to "&MAX(E23:E32) -> : Pre-load from 0 to 100
B21: Meas. Filt: 0.90 Hz Be AutoCal: Off LV:1=0,2=0,3=0,4=0 | D21: Point No. | E21: =L35 -> kgf | F21: kN | I21: raw | J21: zero corrected
D22: Zero | E22: 0 | F22: =IF(E22="","- -",E22*$K$35) -> 0 | G22: =B19 -> 1.1 1.1-DMP40 0.078086 mV/V abs 13-Mar-19 13:04:56 | H22: =RIGHT(G22, LEN(G22)-24) -> 0.078086 mV/V abs 13-Mar-19 13:04:56 | I22: =IFERROR(1*LEFT(H22, LEN(H22)-34), "- - ") -> 0.078086 | J22: =IFERROR(I22-$I$22, "- -") -> 0 | K22: =IFERROR(($J$36*J22+$J$37*J22^2+$J$38*J22^3), "- - ") -> 0
A23: 1st Test point | B23: 1.1 1.1-DMP40 -0.082988 mV/V abs 13-Mar-19 13:06:28 | D23: 1st | E23: 20 | F23: =IF(E23="","- -",E23*$K$35) -> 0.196133 | G23: =B23 -> 1.1 1.1-DMP40 -0.082988 mV/V abs 13-Mar-19 13:06:28 | H23: =RIGHT(G23, LEN(G23)-24) -> -0.082988 mV/V abs 13-Mar-19 13:06:28 | I23: =IFERROR(1*LEFT(H23, LEN(H23)-34), "- - ") -> -0.082988 | J23: =IFERROR(I23-$I$22, "- -") -> -0.161074 | K23: =IFERROR(($J$36*J23+$J$37*J23^2+$J$38*J23^3), "- - ") -> -0.78971043
B24: Excitation: 5.0 V Meas. Range: 2.5 mV/V | D24: 2nd | E24: 40 | F24: =IF(E24="","- -",E24*$K$35) -> 0.392266 | G24: =B27 -> 1.1 1.1-DMP40 -0.242682 mV/V abs 13-Mar-19 13:06:55 | H24: =RIGHT(G24, LEN(G24)-24) -> -0.242682 mV/V abs 13-Mar-19 13:06:55 | I24: =IFERROR(1*LEFT(H24, LEN(H24)-34), "- - ") -> -0.242682 | J24: =IFERROR(I24-$I$22, "- -") -> -0.320768 | K24: =IFERROR(($J$36*J24+$J$37*J24^2+$J$38*J24^3), "- - ") -> -1.5727011
B25: Meas. Filt: 0.90 Hz Be AutoCal: Off LV:1=0,2=0,3=0,4=0 | D25: 3rd | E25: 60 | F25: =IF(E25="","- -",E25*$K$35) -> 0.588399 | G25: =B31 -> 1.1 1.1-DMP40 -0.403444 mV/V abs 13-Mar-19 13:07:17 | H25: =RIGHT(G25, LEN(G25)-24) -> -0.403444 mV/V abs 13-Mar-19 13:07:17 | I25: =IFERROR(1*LEFT(H25, LEN(H25)-34), "- - ") -> -0.403444 | J25: =IFERROR(I25-$I$22, "- -") -> -0.48153 | K25: =IFERROR(($J$36*J25+$J$37*J25^2+$J$38*J25^3), "- - ") -> -2.3609731
D26: 4th | E26: 80 | F26: =IF(E26="","- -",E26*$K$35) -> 0.784532 | G26: =B35 -> 1.1 1.1-DMP40 -0.563466 mV/V abs 13-Mar-19 13:08:12 | H26: =RIGHT(G26, LEN(G26)-24) -> -0.563466 mV/V abs 13-Mar-19 13:08:12 | I26: =IFERROR(1*LEFT(H26, LEN(H26)-34), "- - ") -> -0.563466 | J26: =IFERROR(I26-$I$22, "- -") -> -0.641552 | K26: =IFERROR(($J$36*J26+$J$37*J26^2+$J$38*J26^3), "- - ") -> -3.1456597
A27: 2nd Test point | B27: 1.1 1.1-DMP40 -0.242682 mV/V abs 13-Mar-19 13:06:55 | D27: 5th | E27: 100 | F27: =IF(E27="","- -",E27*$K$35) -> 0.980665 | G27: =B39 -> 1.1 1.1-DMP40 -0.723624 mV/V abs 13-Mar-19 13:09:02 | H27: =RIGHT(G27, LEN(G27)-24) -> -0.723624 mV/V abs 13-Mar-19 13:09:02 | I27: =IFERROR(1*LEFT(H27, LEN(H27)-34), "- - ") -> -0.723624 | J27: =IFERROR(I27-$I$22, "- -") -> -0.80171 | K27: =IFERROR(($J$36*J27+$J$37*J27^2+$J$38*J27^3), "- - ") -> -3.9310546 | M27: =" : Increase load 0 to "&MAX(E28:E37) -> : Increase load 0 to 0
B28: Excitation: 5.0 V Meas. Range: 2.5 mV/V | D28: 6th | F28: =IF(E28="","- -",E28*$K$35) -> - - | G28: =B43 -> 0 | H28: =RIGHT(G28, LEN(G28)-24) -> #VALUE! | I28: =IFERROR(1*LEFT(H28, LEN(H28)-34), "- - ") -> - - | J28: =IFERROR(I28-$I$22, "- -") -> - - | K28: =IFERROR(($J$36*J28+$J$37*J28^2+$J$38*J28^3), "- - ") -> - -
B29: Meas. Filt: 0.90 Hz Be AutoCal: Off LV:1=0,2=0,3=0,4=0 | D29: 7th | F29: =IF(E29="","- -",E29*$K$35) -> - - | G29: =B47 -> 0 | H29: =RIGHT(G29, LEN(G29)-24) -> #VALUE! | I29: =IFERROR(1*LEFT(H29, LEN(H29)-34), "- - ") -> - - | J29: =IFERROR(I29-$I$22, "- -") -> - - | K29: =IFERROR(($J$36*J29+$J$37*J29^2+$J$38*J29^3), "- - ") -> - -
D30: 8th | F30: =IF(E30="","- -",E30*$K$35) -> - - | G30: =B51 -> 0 | H30: =RIGHT(G30, LEN(G30)-24) -> #VALUE! | I30: =IFERROR(1*LEFT(H30, LEN(H30)-34), "- - ") -> - - | J30: =IFERROR(I30-$I$22, "- -") -> - - | K30: =IFERROR(($J$36*J30+$J$37*J30^2+$J$38*J30^3), "- - ") -> - -
A31: 3rd Test point | B31: 1.1 1.1-DMP40 -0.403444 mV/V abs 13-Mar-19 13:07:17 | D31: 9th | F31: =IF(E31="","- -",E31*$K$35) -> - - | G31: =B55 -> 0 | H31: =RIGHT(G31, LEN(G31)-24) -> #VALUE! | I31: =IFERROR(1*LEFT(H31, LEN(H31)-34), "- - ") -> - - | J31: =IFERROR(I31-$I$22, "- -") -> - - | K31: =IFERROR(($J$36*J31+$J$37*J31^2+$J$38*J31^3), "- - ") -> - -
B32: Excitation: 5.0 V Meas. Range: 2.5 mV/V | D32: 10th | F32: =IF(E32="","- -",E32*$K$35) -> - - | G32: =B59 -> 0 | H32: =RIGHT(G32, LEN(G32)-24) -> #VALUE! | I32: =IFERROR(1*LEFT(H32, LEN(H32)-34), "- - ") -> - - | J32: =IFERROR(I32-$I$22, "- -") -> - - | K32: =IFERROR(($J$36*J32+$J$37*J32^2+$J$38*J32^3), "- - ") -> - -
B33: Meas. Filt: 0.90 Hz Be AutoCal: Off LV:1=0,2=0,3=0,4=0 | D33: Zero | E33: 0 | F33: =IF(E33="","- -",E33*$K$35) -> 0 | G33: =B63 -> 1.1 1.1-DMP40 0.077444 mV/V abs 13-Mar-19 13:10:36 | H33: =RIGHT(G33, LEN(G33)-24) -> 0.077444 mV/V abs 13-Mar-19 13:10:36 | I33: =IFERROR(1*LEFT(H33, LEN(H33)-34), "- - ") -> 0.077444 | J33: =IFERROR(I33-$I$22, "- -") -> -0.000642 | K33: =IFERROR(($J$36*J33+$J$37*J33^2+$J$38*J33^3), "- - ") -> -0.0031474901
D34: Force Transducer Information
A35: 4th Test point | B35: 1.1 1.1-DMP40 -0.563466 mV/V abs 13-Mar-19 13:08:12 | K35: 0.00980665 | L35: kgf
B36: Excitation: 5.0 V Meas. Range: 2.5 mV/V | D36: Load Cell | E36: HBM/C3H3 | H36: =IF($F$6="Compression",6,10) -> 6 | I36: A | J36: =VLOOKUP($E$36,Table1[],H36,FALSE) -> 4.902632
B37: Meas. Filt: 0.90 Hz Be AutoCal: Off LV:1=0,2=0,3=0,4=0 | D37: Capacity | E37: =VLOOKUP($E$36,Table1[],2,FALSE) -> 10 kN | H37: =IF($F$6="Compression",7,11) -> 7 | I37: B | J37: =VLOOKUP($E$36,Table1[],H37,FALSE) -> -0.0009307508
D38: Serial No. | E38: =VLOOKUP($E$36,Table1[],3,FALSE) -> F93007 | H38: =IF($F$6="Compression",8,12) -> 8 | I38: C | J38: =VLOOKUP($E$36,Table1[],H38,FALSE) -> -6.355071e-05
A39: 5th Test point | B39: 1.1 1.1-DMP40 -0.723624 mV/V abs 13-Mar-19 13:09:02 | D39: Cal. Cert. No. | E39: =VLOOKUP($E$36,Table1[],4,FALSE) -> 1800-00040-004 | H39: =IF($F$6="Compression",9,13) -> 9 | I39: U, % | J39: =VLOOKUP($E$36,Table1[],H39,FALSE) -> 0.011
B40: Excitation: 5.0 V Meas. Range: 2.5 mV/V | D40: Cal Date | E40: =VLOOKUP($E$36,Table1[],5,FALSE) -> 43161 | G40: =VLOOKUP($E$36,Table1[],14,FALSE) -> 44257 | H40: =IF($F$6="Compression",10,14) -> 10 | I40: k | J40: 2
B41: Meas. Filt: 0.90 Hz Be AutoCal: Off LV:1=0,2=0,3=0,4=0
...

Sheet Calibration Data
A1: FORCE MEASUREMENT DATA
A2: Ver. 2 Rev.0 Mar 12, 2019
A3: revised & developed by: gearnhale@yahoo.com according to ISO
A4: original developer: manuelmruiz@yahoo.com
A6: Certificate No. | C6: ='Dash Board'!D18 -> 03-2026-FORC-0087
A7: Client Name: | C7: ='Dash Board'!D7 -> SAVVICE CORPORATION
A8: Calibration Date: | C8: ='Dash Board'!D17 -> 46134
A9: Client Address: | C9: ='Dash Board'!D8&" "&'Dash Board'!D9 -> 3rd Floor BMWC Bldg., Cagayan Valley Road Sta. Rita, Guiginto, Bulacan | J9: Calibration Mode: | L9: ='Dash Board'!N17 -> Compression
A10: Calibration Item: | C10: ='Dash Board'!D19 -> Axle Weighing Scale | J10: Machine Capacity: | L10: ='Dash Board'!N18&" "&'Dash Board'!O18 -> 15000 kgf
A11: Model Code/No: | C11: ='Dash Board'!D23 -> LS 630 W. PAD | J11: Calibration Range: | L11: ='Dash Board'!N19&'Dash Board'!O19&'Dash Board'!P19&" "&'Dash Board'!Q19 -> 0 kgf to 15000 kgf
A12: Serial No/ ID No. | C12: ='Dash Board'!D24 -> 0122YL21002 | J12: Increment | L12: ='Dash Board'!N21 &" "& 'Dash Board'!O24 -> 50
A13: Remarks: | C13: ='Dash Board'!D29&" "&'Dash Board'!D30 | J13: Resolution | L13: ='Dash Board'!N24 &" "& 'Dash Board'!O24
B15: 1. Preloading
C16: Indicated Force | D16: Load 1st (0˚) | E16: Indicated Force | F16: Load 2nd (120˚) | G16: Indicated Force | H16: Load 3rd (240˚) | J16: Reference Standard Used: | L16: =Software!E36 -> HBM/C3H3 | P16: Temp.: | Q16: Humidity:
C17: =Software!F45 -> 0 | D17: =Software!I45 -> 0.078086 | E17: =Software!F52 -> 0 | F17: =Software!I52 -> 0.078086 | G17: =Software!F59 -> 0 | H17: =Software!I59 -> 0.078086 | J17: ="Capacity: "&Software!E37 -> Capacity: 10 kN | L17: a' | M17: =Software!J36 -> 4.902632 | P17: =Software!E14 -> 25 | Q17: =Software!E15 -> 33
C18: =Software!F46 -> 0.196133 | D18: =Software!I46 -> -0.082988 | E18: =Software!F53 -> 0.196133 | F18: =Software!I53 -> -0.082988 | G18: =Software!F60 -> 0.196133 | H18: =Software!I60 -> -0.082988 | J18: ="Serial #: "&Software!E38 -> Serial #: F93007 | L18: b' | M18: =Software!J37 -> -0.0009307508 | P18: =Software!F14 -> 25 | Q18: =Software!F15 -> 33 | AE18: Relative Expanded Uncertainty | AH18: Relative standard uncertainty of force measuring instrument wstd | AX18: =N25/AE24 -> #DIV/0!
C19: =Software!F47 -> 0 | D19: =Software!I47 -> 0.077444 | E19: =Software!F54 -> 0 | F19: =Software!I54 -> 0.077444 | G19: =Software!F61 -> 0 | H19: =Software!I61 -> 0.077444 | J19: ="Cal Cert #: "&Software!E39 -> Cal Cert #: 1800-00040-004 | L19: c' | M19: =Software!J38 -> -6.355071e-05 | P19: =AVERAGE(P17:P18) -> 25 | Q19: =AVERAGE(Q17:Q18) -> 33
V20: RAW DATA CALCULATION | AF20: Relative uncertainty by reproducibility (wrep,i) | AG20: Relative uncertainty due to resolution (wres,i) | AH20: Calibration uncertainty (wstdc) | AI20: Uncertainty due to temperature difference (wtemp') | AJ20: Uncertainty due to sensitivity drift (wdrift) | AK20: Relative standard uncertainty (wstd) | AL20: Relative combined uncertainty (wci) | AM20: Effective degree of freedom | AN20: coverage factor (k) | AO20: Relative expanded uncertainty (Wi) | AQ20: Relative accu error qi | AR20: Relative rep error bi | AS20: Relative zero error f0 | AU20: Relative accuracy error qi | AV20: Relative repeatability error bi | AW20: Relative zero error f0 | AX20: Lower Limit of calibration range | AY20: Relative uncertainty of force measuring instrument 상대불확도 | AZ20: Class
B21: 2. Linear Interpolation (of reference force deflection) | I21: 3. Estimation of reference force | V21: Net Value (dij) & Mean (di) Calculation | AE21: =Software!J39 -> 0.011
C22: Force (kN) | D22: Load Value | J22: Force (kN) | K22: Load Value (kN) | T22: Machine Indication | V22: Indicated Force | W22: Load 1st (0˚) | X22: Indicated Force | Y22: Load 2nd (120˚) | Z22: Indicated Force | AA22: Load 3rd (240˚) | AB22: Mean Value | AC22: Applied Force | AE22: Resolution testing machine
D23: 1st (0˚) | E23: 2nd (120˚) | F23: 3rd (240˚) | G23: Mean Value | K23: 1st (0˚) | L23: 2nd (120˚) | M23: 3rd (240˚) | N23: Mean Value | T23: Indicated Force | U23: Equivalent Force (kN)
C24: 0 | D24: 0 | E24: 0 | F24: 0 | G24: =ROUND((M17*Z24+M18*Z24^2)*1000,0) -> 0 | J24: =U24 -> 0 | K24: -0.004913 | L24: 0 | M24: -0.004913 | N24: 0 | T24: ='Dash Board'!T8 -> 0 | U24: =T24*Software!$K$35 -> 0 | V24: =Software!F66 -> 0 | W24: =Software!J66 -> 0 | X24: =Software!F82 -> 0 | Y24: =Software!J82 -> 0 | Z24: =Software!F98 -> 0 | AA24: =Software!J98 -> 0 | AB24: =ROUND(AVERAGE(W24,Y24,AA24),5) -> 0 | AC24: =N24 -> 0 | AE24: ='Dash Board'!N24*Software!K35 -> 0 | AF24: 0 | AG24: 0 | AH24: 0 | AI24: 0 | AJ24: 0 | AK24: 0 | AL24: 0 | AM24: - | AN24: - | AO24: 0 | AQ24: 0 | AR24: 0 | AS24: 0 | AU24: - | AV24: - | AW24: - | AX24: - | AY24: - | AZ24: -
C25: =U25 -> 29.41995 | D25: =W25*$U25/$V25 -> -24.1611 | E25: =Y25*$U25/$X25 -> -24.1611 | F25: =AA25*U25/Z25 -> -24.1611 | G25: =ROUND(AVERAGE(D25:F25),5) -> -24.1611 | J25: =U25 -> 29.41995 | K25: =ABS(ROUND((($M$17*D25+$M$18*D25^2+$M$19*D25^3)),3)) -> 118.1 | L25: =ABS(ROUND((($M$17*E25+$M$18*E25^2+$M$19*E25^3)),3)) -> 118.1 | M25: =ABS(ROUND((($M$17*F25+$M$18*F25^2+$M$19*F25^3)),3)) -> 118.1 | N25: =ABS(ROUND(AVERAGE(K25:M25),3)) -> 118.1 | T25: ='Dash Board'!T9 -> 3000 | U25: =T25*Software!$K$35 -> 29.41995 | V25: =Software!F67 -> 0.196133 | W25: =Software!J67 -> -0.161074 | X25: =Software!F83 -> 0.196133 | Y25: =Software!J83 -> -0.161074 | Z25: =Software!F99 -> 0.196133 | AA25: =Software!J99 -> -0.161074 | AB25: =ROUND(AVERAGE(W25,Y25,AA25),5) -> -0.16107 | AC25: =N25 -> 118.1 | AE25: Sensitivity on temp | AF25: =((100/N25)*(SQRT(((K25-N25)^2+(L25-N25)^2+(M25-N25)^2)/2)))/SQRT(3) -> 0 | AG25: =($AE$24*100)/(N25*2*SQRT(3)) -> 0 | AH25: =$AE$21/2 -> 0.0055 | AI25: =($AE$27*$AE$29)/SQRT(3) -> 0 | AJ25: =$AE$31/SQRT(3) -> 0.028867513 | AK25: =SQRT((SUMSQ(AH25:AJ25))) -> 0.029386788 | AL25: =SQRT(SUMSQ(AF25,AG25,AK25)) -> 0.029386788 | AM25: =ROUNDDOWN(AL25^4/AF25^4*2,0) -> #DIV/0! | AN25: 2 | AO25: =AN25*AL25 -> 0.058773577 | AQ25: =((J25-N25)/N25)*100 -> -75.08895 | AR25: =(MAX(K25,L25,M25)-MIN(K25,L25,M25))/N25*100 -> 0 | AS25: =$V$36/IF($J$34<>0,$J$34,$J$29)*100 -> 0 | AU25: =IF(ABS(AQ25)<=0.5,0.5,IF(ABS(AQ25)<=1,1,IF(ABS(AQ25)<=2,2,IF(ABS(AQ25)<=3,3,"-")))) -> - | AV25: =IF(AR25<=0.5,0.5,IF(AR25<=1,1,IF(AR25<=2,2,IF(AR25<=3,3,"-")))) -> 0.5 | AW25: =IF(ABS(AS25)<=0.05,0.5,IF(ABS(AS25)<=0.1,1,IF(ABS(AS25)<=0.2,2,IF(ABS(AS25)<=0.3,3,"-")))) -> 0.5 | AX25: =IF($AX$18>=400,0.5,IF($AX$18>=200,1,IF($AX$18>=100,2,IF($AX$18>=67,3,"-")))) -> #DIV/0! | AY25: =IF($AE$21<=0.12,0.5,IF($AE$21<=0.25,1,IF($AE$21<=0.5,2,"-"))) -> 0.5 | AZ25: =MAX(AU25,AV25,AW25,AY25) -> 0.5
C26: =U26 -> 58.8399 | D26: =W26*$U26/$V26 -> -48.1152 | E26: =Y26*$U26/$X26 -> -48.1152 | F26: =AA26*U26/Z26 -> -48.1152 | G26: =ROUND(AVERAGE(D26:F26),5) -> -48.1152 | J26: =U26 -> 58.8399 | K26: =ABS(ROUND((($M$17*D26+$M$18*D26^2+$M$19*D26^3)),3)) -> 230.967 | L26: =ABS(ROUND((($M$17*E26+$M$18*E26^2+$M$19*E26^3)),3)) -> 230.967 | M26: =ABS(ROUND((($M$17*F26+$M$18*F26^2+$M$19*F26^3)),3)) -> 230.967 | N26: =ABS(ROUND(AVERAGE(K26:M26),3)) -> 230.967 | T26: ='Dash Board'!T10 -> 6000 | U26: =T26*Software!$K$35 -> 58.8399 | V26: =Software!F68 -> 0.392266 | W26: =Software!J68 -> -0.320768 | X26: =Software!F84 -> 0.392266 | Y26: =Software!J84 -> -0.320768 | Z26: =Software!F100 -> 0.392266 | AA26: =Software!J100 -> -0.320768 | AB26: =ROUND(AVERAGE(W26,Y26,AA26),5) -> -0.32077 | AC26: =N26 -> 230.967 | AF26: =((100/N26)*(SQRT(((K26-N26)^2+(L26-N26)^2+(M26-N26)^2)/2)))/SQRT(3) -> 0 | AG26: =($AE$24*100)/(N26*2*SQRT(3)) -> 0 | AH26: =$AE$21/2 -> 0.0055 | AI26: =($AE$27*$AE$29)/SQRT(3) -> 0 | AJ26: =$AE$31/SQRT(3) -> 0.028867513 | AK26: =SQRT((SUMSQ(AH26:AJ26))) -> 0.029386788 | AL26: =SQRT(SUMSQ(AF26,AG26,AK26)) -> 0.029386788 | AM26: =ROUNDDOWN(AL26^4/AF26^4*2,0) -> #DIV/0! | AN26: 2 | AO26: =AN26*AL26 -> 0.058773577 | AQ26: =((J26-N26)/N26)*100 -> -74.524542 | AR26: =(MAX(K26,L26,M26)-MIN(K26,L26,M26))/N26*100 -> 0 | AS26: =$V$36/IF($J$29<>0,$J$29,$J$29)*100 -> 0 | AU26: =IF(ABS(AQ26)<=0.5,0.5,IF(ABS(AQ26)<=1,1,IF(ABS(AQ26)<=2,2,IF(ABS(AQ26)<=3,3,"-")))) -> - | AV26: =IF(AR26<=0.5,0.5,IF(AR26<=1,1,IF(AR26<=2,2,IF(AR26<=3,3,"-")))) -> 0.5 | AW26: =IF(ABS(AS26)<=0.05,0.5,IF(ABS(AS26)<=0.1,1,IF(ABS(AS26)<=0.2,2,IF(ABS(AS26)<=0.3,3,"-")))) -> 0.5 | AX26: =IF($AX$18>=400,0.5,IF($AX$18>=200,1,IF($AX$18>=100,2,IF($AX$18>=67,3,"-")))) -> #DIV/0! | AY26: =IF($AE$21<=0.12,0.5,IF($AE$21<=0.25,1,IF($AE$21<=0.5,2,"-"))) -> 0.5 | AZ26: =MAX(AU26,AV26,AW26,AY26) -> 0.5
C27: =U27 -> 88.25985 | D27: =W27*$U27/$V27 -> -72.2295 | E27: =Y27*$U27/$X27 -> -72.2295 | F27: =AA27*U27/Z27 -> -72.2295 | G27: =ROUND(AVERAGE(D27:F27),5) -> -72.2295 | J27: =U27 -> 88.25985 | K27: =ABS(ROUND((($M$17*D27+$M$18*D27^2+$M$19*D27^3)),3)) -> 335.023 | L27: =ABS(ROUND((($M$17*E27+$M$18*E27^2+$M$19*E27^3)),3)) -> 335.023 | M27: =ABS(ROUND((($M$17*F27+$M$18*F27^2+$M$19*F27^3)),3)) -> 335.023 | N27: =ABS(ROUND(AVERAGE(K27:M27),3)) -> 335.023 | T27: ='Dash Board'!T11 -> 9000 | U27: =T27*Software!$K$35 -> 88.25985 | V27: =Software!F69 -> 0.588399 | W27: =Software!J69 -> -0.48153 | X27: =Software!F85 -> 0.588399 | Y27: =Software!J85 -> -0.48153 | Z27: =Software!F101 -> 0.588399 | AA27: =Software!J101 -> -0.48153 | AB27: =ROUND(AVERAGE(W27,Y27,AA27),5) -> -0.48153 | AC27: =N27 -> 335.023 | AE27: 0.003 | AF27: =((100/N27)*(SQRT(((K27-N27)^2+(L27-N27)^2+(M27-N27)^2)/2)))/SQRT(3) -> 0 | AG27: =($AE$24*100)/(N27*2*SQRT(3)) -> 0 | AH27: =$AE$21/2 -> 0.0055 | AI27: =($AE$27*$AE$29)/SQRT(3) -> 0 | AJ27: =$AE$31/SQRT(3) -> 0.028867513 | AK27: =SQRT((SUMSQ(AH27:AJ27))) -> 0.029386788 | AL27: =SQRT(SUMSQ(AF27,AG27,AK27)) -> 0.029386788 | AM27: =ROUNDDOWN(AL27^4/AF27^4*2,0) -> #DIV/0! | AN27: 2 | AO27: =AN27*AL27 -> 0.058773577 | AQ27: =((J27-N27)/N27)*100 -> -73.655585 | AR27: =(MAX(K27,L27,M27)-MIN(K27,L27,M27))/N27*100 -> 0 | AS27: =$V$36/IF($J$29<>0,$J$29,$J$29)*100 -> 0 | AU27: =IF(ABS(AQ27)<=0.5,0.5,IF(ABS(AQ27)<=1,1,IF(ABS(AQ27)<=2,2,IF(ABS(AQ27)<=3,3,"-")))) -> - | AV27: =IF(AR27<=0.5,0.5,IF(AR27<=1,1,IF(AR27<=2,2,IF(AR27<=3,3,"-")))) -> 0.5 | AW27: =IF(ABS(AS27)<=0.05,0.5,IF(ABS(AS27)<=0.1,1,IF(ABS(AS27)<=0.2,2,IF(ABS(AS27)<=0.3,3,"-")))) -> 0.5 | AX27: =IF($AX$18>=400,0.5,IF($AX$18>=200,1,IF($AX$18>=100,2,IF($AX$18>=67,3,"-")))) -> #DIV/0! | AY27: =IF($AE$21<=0.12,0.5,IF($AE$21<=0.25,1,IF($AE$21<=0.5,2,"-"))) -> 0.5 | AZ27: =MAX(AU27,AV27,AW27,AY27) -> 0.5
C28: =U28 -> 117.6798 | D28: =W28*$U28/$V28 -> -96.2328 | E28: =Y28*$U28/$X28 -> -96.2328 | F28: =AA28*U28/Z28 -> -96.2328 | G28: =ROUND(AVERAGE(D28:F28),5) -> -96.2328 | J28: =U28 -> 117.6798 | K28: =ABS(ROUND((($M$17*D28+$M$18*D28^2+$M$19*D28^3)),3)) -> 423.778 | L28: =ABS(ROUND((($M$17*E28+$M$18*E28^2+$M$19*E28^3)),3)) -> 423.778 | M28: =ABS(ROUND((($M$17*F28+$M$18*F28^2+$M$19*F28^3)),3)) -> 423.778 | N28: =ABS(ROUND(AVERAGE(K28:M28),3)) -> 423.778 | T28: ='Dash Board'!T12 -> 12000 | U28: =T28*Software!$K$35 -> 117.6798 | V28: =Software!F70 -> 0.784532 | W28: =Software!J70 -> -0.641552 | X28: =Software!F86 -> 0.784532 | Y28: =Software!J86 -> -0.641552 | Z28: =Software!F102 -> 0.784532 | AA28: =Software!J102 -> -0.641552 | AB28: =ROUND(AVERAGE(W28,Y28,AA28),5) -> -0.64155 | AC28: =N28 -> 423.778 | AE28: Temp Diff. | AF28: =((100/N28)*(SQRT(((K28-N28)^2+(L28-N28)^2+(M28-N28)^2)/2)))/SQRT(3) -> 0 | AG28: =($AE$24*100)/(N28*2*SQRT(3)) -> 0 | AH28: =$AE$21/2 -> 0.0055 | AI28: =($AE$27*$AE$29)/SQRT(3) -> 0 | AJ28: =$AE$31/SQRT(3) -> 0.028867513 | AK28: =SQRT((SUMSQ(AH28:AJ28))) -> 0.029386788 | AL28: =SQRT(SUMSQ(AF28,AG28,AK28)) -> 0.029386788 | AM28: =ROUNDDOWN(AL28^4/AF28^4*2,0) -> #DIV/0! | AN28: 2 | AO28: =AN28*AL28 -> 0.058773577 | AQ28: =((J28-N28)/N28)*100 -> -72.230791 | AR28: =(MAX(K28,L28,M28)-MIN(K28,L28,M28))/N28*100 -> 0 | AS28: =$V$36/IF($J$29<>0,$J$29,$J$29)*100 -> 0 | AU28: =IF(ABS(AQ28)<=0.5,0.5,IF(ABS(AQ28)<=1,1,IF(ABS(AQ28)<=2,2,IF(ABS(AQ28)<=3,3,"-")))) -> - | AV28: =IF(AR28<=0.5,0.5,IF(AR28<=1,1,IF(AR28<=2,2,IF(AR28<=3,3,"-")))) -> 0.5 | AW28: =IF(ABS(AS28)<=0.05,0.5,IF(ABS(AS28)<=0.1,1,IF(ABS(AS28)<=0.2,2,IF(ABS(AS28)<=0.3,3,"-")))) -> 0.5 | AX28: =IF($AX$18>=400,0.5,IF($AX$18>=200,1,IF($AX$18>=100,2,IF($AX$18>=67,3,"-")))) -> #DIV/0! | AY28: =IF($AE$21<=0.12,0.5,IF($AE$21<=0.25,1,IF($AE$21<=0.5,2,"-"))) -> 0.5 | AZ28: =MAX(AU28,AV28,AW28,AY28) -> 0.5
C29: =U29 -> 147.09975 | D29: =W29*$U29/$V29 -> -120.2565 | E29: =Y29*$U29/$X29 -> -120.2565 | F29: =AA29*U29/Z29 -> -120.2565 | G29: =ROUND(AVERAGE(D29:F29),5) -> -120.2565 | J29: =U29 -> 147.09975 | K29: =ABS(ROUND((($M$17*D29+$M$18*D29^2+$M$19*D29^3)),3)) -> 492.512 | L29: =ABS(ROUND((($M$17*E29+$M$18*E29^2+$M$19*E29^3)),3)) -> 492.512 | M29: =ABS(ROUND((($M$17*F29+$M$18*F29^2+$M$19*F29^3)),3)) -> 492.512 | N29: =ABS(ROUND(AVERAGE(K29:M29),3)) -> 492.512 | T29: ='Dash Board'!T13 -> 15000 | U29: =T29*Software!$K$35 -> 147.09975 | V29: =Software!F71 -> 0.980665 | W29: =Software!J71 -> -0.80171 | X29: =Software!F87 -> 0.980665 | Y29: =Software!J87 -> -0.80171 | Z29: =Software!F103 -> 0.980665 | AA29: =Software!J103 -> -0.80171 | AB29: =ROUND(AVERAGE(W29,Y29,AA29),5) -> -0.80171 | AC29: =N29 -> 492.512 | AE29: =ABS(P17-P18) -> 0 | AF29: =((100/N29)*(SQRT(((K29-N29)^2+(L29-N29)^2+(M29-N29)^2)/2)))/SQRT(3) -> 0 | AG29: =($AE$24*100)/(N29*2*SQRT(3)) -> 0 | AH29: =$AE$21/2 -> 0.0055 | AI29: =($AE$27*$AE$29)/SQRT(3) -> 0 | AJ29: =$AE$31/SQRT(3) -> 0.028867513 | AK29: =SQRT((SUMSQ(AH29:AJ29))) -> 0.029386788 | AL29: =SQRT(SUMSQ(AF29,AG29,AK29)) -> 0.029386788 | AM29: =ROUNDDOWN(AL29^4/AF29^4*2,0) -> #DIV/0! | AN29: 2 | AO29: =AN29*AL29 -> 0.058773577 | AQ29: =((J29-N29)/N29)*100 -> -70.132758 | AR29: =(MAX(K29,L29,M29)-MIN(K29,L29,M29))/N29*100 -> 0 | AS29: =$V$36/IF($J$29<>0,$J$29,$J$29)*100 -> 0 | AU29: =IF(ABS(AQ29)<=0.5,0.5,IF(ABS(AQ29)<=1,1,IF(ABS(AQ29)<=2,2,IF(ABS(AQ29)<=3,3,"-")))) -> - | AV29: =IF(AR29<=0.5,0.5,IF(AR29<=1,1,IF(AR29<=2,2,IF(AR29<=3,3,"-")))) -> 0.5 | AW29: =IF(ABS(AS29)<=0.05,0.5,IF(ABS(AS29)<=0.1,1,IF(ABS(AS29)<=0.2,2,IF(ABS(AS29)<=0.3,3,"-")))) -> 0.5 | AX29: =IF($AX$18>=400,0.5,IF($AX$18>=200,1,IF($AX$18>=100,2,IF($AX$18>=67,3,"-")))) -> #DIV/0! | AY29: =IF($AE$21<=0.12,0.5,IF($AE$21<=0.25,1,IF($AE$21<=0.5,2,"-"))) -> 0.5 | AZ29: =MAX(AU29,AV29,AW29,AY29) -> 0.5
C30: =U30 -> 0 | D30: =IFERROR(ROUND(W30*$U30/$V30,5),"- -") -> - - | E30: =IFERROR(ROUND(Y30*$U30/$X30,5),"- -") -> - - | F30: =IFERROR(ROUND(AA30*$U30/$Z30,5),"- -") -> - - | G30: =IFERROR(ROUND(AVERAGE(D30:F30),5),"- -") -> - - | J30: =U30 -> 0 | K30: =IFERROR(ROUND((($M$17*D30+$M$18*D30^2+$M$19*D30^3)),3),"- -") -> - - | L30: =IFERROR(ROUND((($M$17*E30+$M$18*E30^2+$M$19*E30^3)),3),"- -") -> - - | M30: =IFERROR(ROUND((($M$17*F30+$M$18*F30^2+$M$19*F30^3)),3),"- -") -> - - | N30: =IFERROR(ROUND(AVERAGE(K30:M30),3),"- -") -> - - | T30: =IFERROR('Dash Board'!T14,"- -") -> 0 | U30: =T30*Software!$K$35 -> 0 | V30: =Software!F72 -> - - | W30: =Software!J72 -> - - | X30: =Software!F88 -> - - | Y30: =Software!J88 -> - - | Z30: =Software!F104 -> - - | AA30: =Software!J104 -> - - | AB30: =IFERROR(ROUND(AVERAGE(W30,Y30,AA30),5),"- -") -> - - | AC30: =N30 -> - - | AE30: Drift Sens. | AF30: =((100/N30)*(SQRT(((K30-N30)^2+(L30-N30)^2+(M30-N30)^2)/2)))/SQRT(3) -> #VALUE! | AG30: =($AE$24*100)/(N30*2*SQRT(3)) -> #VALUE! | AH30: =$AE$21/2 -> 0.0055 | AI30: =($AE$27*$AE$29)/SQRT(3) -> 0 | AJ30: =$AE$31/SQRT(3) -> 0.028867513 | AK30: =SQRT((SUMSQ(AH30:AJ30))) -> 0.029386788 | AL30: =SQRT(SUMSQ(AF30,AG30,AK30)) -> #VALUE! | AN30: 2 | AO30: =AN30*AL30 -> #VALUE! | AQ30: =IFERROR(((J30-N30)/N30)*100,"- -") -> - - | AR30: =IFERROR((MAX(K30,L30,M30)-MIN(K30,L30,M30))/N30*100,"- -") -> - - | AS30: =$V$36/IF($J$29<>0,$J$29,$J$29)*100 -> 0 | AU30: =IF(ABS(AQ30)<=0.5,0.5,IF(ABS(AQ30)<=1,1,IF(ABS(AQ30)<=2,2,IF(ABS(AQ30)<=3,3,"-")))) -> #VALUE! | AV30: =IF(AR30<=0.5,0.5,IF(AR30<=1,1,IF(AR30<=2,2,IF(AR30<=3,3,"-")))) -> - | AW30: =IF(ABS(AS30)<=0.05,0.5,IF(ABS(AS30)<=0.1,1,IF(ABS(AS30)<=0.2,2,IF(ABS(AS30)<=0.3,3,"-")))) -> 0.5 | AX30: =IF($AX$18>=400,0.5,IF($AX$18>=200,1,IF($AX$18>=100,2,IF($AX$18>=67,3,"-")))) -> #DIV/0! | AY30: =IF($AE$21<=0.12,0.5,IF($AE$21<=0.25,1,IF($AE$21<=0.5,2,"-"))) -> 0.5 | AZ30: =MAX(AU30,AV30,AW30,AY30) -> #VALUE!
C31: =U31 -> 0 | D31: =IFERROR(ROUND(W31*$U31/$V31,5),"- -") -> - - | E31: =IFERROR(ROUND(Y31*$U31/$X31,5),"- -") -> - - | F31: =IFERROR(ROUND(AA31*$U31/$Z31,5),"- -") -> - - | G31: =IFERROR(ROUND(AVERAGE(D31:F31),5),"- -") -> - - | J31: =U31 -> 0 | K31: =IFERROR(ROUND((($M$17*D31+$M$18*D31^2+$M$19*D31^3)),3),"- -") -> - - | L31: =IFERROR(ROUND((($M$17*E31+$M$18*E31^2+$M$19*E31^3)),3),"- -") -> - - | M31: =IFERROR(ROUND((($M$17*F31+$M$18*F31^2+$M$19*F31^3)),3),"- -") -> - - | N31: =IFERROR(ROUND(AVERAGE(K31:M31),3),"- -") -> - - | T31: =IFERROR('Dash Board'!T15,"- -") -> 0 | U31: =T31*Software!$K$35 -> 0 | V31: =Software!F73 -> - - | W31: =Software!J73 -> - - | X31: =Software!F89 -> - - | Y31: =Software!J89 -> - - | Z31: =Software!F105 -> - - | AA31: =Software!J105 -> - - | AB31: =IFERROR(ROUND(AVERAGE(W31,Y31,AA31),5),"- -") -> - - | AC31: =N31 -> - - | AE31: 0.05 | AF31: =((100/N31)*(SQRT(((K31-N31)^2+(L31-N31)^2+(M31-N31)^2)/2)))/SQRT(3) -> #VALUE! | AG31: =($AE$24*100)/(N31*2*SQRT(3)) -> #VALUE! | AH31: =$AE$21/2 -> 0.0055 | AI31: =($AE$27*$AE$29)/SQRT(3) -> 0 | AJ31: =$AE$31/SQRT(3) -> 0.028867513 | AK31: =SQRT((SUMSQ(AH31:AJ31))) -> 0.029386788 | AL31: =SQRT(SUMSQ(AF31,AG31,AK31)) -> #VALUE! | AN31: 2 | AO31: =AN31*AL31 -> #VALUE! | AQ31: =IFERROR(((J31-N31)/N31)*100,"- -") -> - - | AR31: =IFERROR((MAX(K31,L31,M31)-MIN(K31,L31,M31))/N31*100,"- -") -> - - | AS31: =$V$36/IF($J$29<>0,$J$29,$J$29)*100 -> 0 | AU31: =IF(ABS(AQ31)<=0.5,0.5,IF(ABS(AQ31)<=1,1,IF(ABS(AQ31)<=2,2,IF(ABS(AQ31)<=3,3,"-")))) -> #VALUE! | AV31: =IF(AR31<=0.5,0.5,IF(AR31<=1,1,IF(AR31<=2,2,IF(AR31<=3,3,"-")))) -> - | AW31: =IF(ABS(AS31)<=0.05,0.5,IF(ABS(AS31)<=0.1,1,IF(ABS(AS31)<=0.2,2,IF(ABS(AS31)<=0.3,3,"-")))) -> 0.5 | AX31: =IF($AX$18>=400,0.5,IF($AX$18>=200,1,IF($AX$18>=100,2,IF($AX$18>=67,3,"-")))) -> #DIV/0! | AY31: =IF($AE$21<=0.12,0.5,IF($AE$21<=0.25,1,IF($AE$21<=0.5,2,"-"))) -> 0.5 | AZ31: =MAX(AU31,AV31,AW31,AY31) -> #VALUE!
C32: =U32 -> 0 | D32: =IFERROR(ROUND(W32*$U32/$V32,5),"- -") -> - - | E32: =IFERROR(ROUND(Y32*$U32/$X32,5),"- -") -> - - | F32: =IFERROR(ROUND(AA32*$U32/$Z32,5),"- -") -> - - | G32: =IFERROR(ROUND(AVERAGE(D32:F32),5),"- -") -> - - | J32: =U32 -> 0 | K32: =IFERROR(ROUND((($M$17*D32+$M$18*D32^2+$M$19*D32^3)),3),"- -") -> - - | L32: =IFERROR(ROUND((($M$17*E32+$M$18*E32^2+$M$19*E32^3)),3),"- -") -> - - | M32: =IFERROR(ROUND((($M$17*F32+$M$18*F32^2+$M$19*F32^3)),3),"- -") -> - - | N32: =IFERROR(ROUND(AVERAGE(K32:M32),3),"- -") -> - - | T32: =IFERROR('Dash Board'!T16,"- -") -> 0 | U32: =T32*Software!$K$35 -> 0 | V32: =Software!F74 -> - - | W32: =Software!J74 -> - - | X32: =Software!F90 -> - - | Y32: =Software!J90 -> - - | Z32: =Software!F106 -> - - | AA32: =Software!J106 -> - - | AB32: =IFERROR(ROUND(AVERAGE(W32,Y32,AA32),5),"- -") -> - - | AC32: =N32 -> - - | AF32: =((100/N32)*(SQRT(((K32-N32)^2+(L32-N32)^2+(M32-N32)^2)/2)))/SQRT(3) -> #VALUE! | AG32: =($AE$24*100)/(N32*2*SQRT(3)) -> #VALUE! | AH32: =$AE$21/2 -> 0.0055 | AI32: =($AE$27*$AE$29)/SQRT(3) -> 0 | AJ32: =$AE$31/SQRT(3) -> 0.028867513 | AK32: =SQRT((SUMSQ(AH32:AJ32))) -> 0.029386788 | AL32: =SQRT(SUMSQ(AF32,AG32,AK32)) -> #VALUE! | AN32: 2 | AO32: =AN32*AL32 -> #VALUE! | AQ32: =IFERROR(((J32-N32)/N32)*100,"- -") -> - - | AR32: =IFERROR((MAX(K32,L32,M32)-MIN(K32,L32,M32))/N32*100,"- -") -> - - | AS32: =$V$36/IF($J$29<>0,$J$29,$J$29)*100 -> 0 | AU32: =IF(ABS(AQ32)<=0.5,0.5,IF(ABS(AQ32)<=1,1,IF(ABS(AQ32)<=2,2,IF(ABS(AQ32)<=3,3,"-")))) -> #VALUE! | AV32: =IF(AR32<=0.5,0.5,IF(AR32<=1,1,IF(AR32<=2,2,IF(AR32<=3,3,"-")))) -> - | AW32: =IF(ABS(AS32)<=0.05,0.5,IF(ABS(AS32)<=0.1,1,IF(ABS(AS32)<=0.2,2,IF(ABS(AS32)<=0.3,3,"-")))) -> 0.5 | AX32: =IF($AX$18>=400,0.5,IF($AX$18>=200,1,IF($AX$18>=100,2,IF($AX$18>=67,3,"-")))) -> #DIV/0! | AY32: =IF($AE$21<=0.12,0.5,IF($AE$21<=0.25,1,IF($AE$21<=0.5,2,"-"))) -> 0.5 | AZ32: =MAX(AU32,AV32,AW32,AY32) -> #VALUE!
C33: =U33 -> 0 | D33: =IFERROR(ROUND(W33*$U33/$V33,5),"- -") -> - - | E33: =IFERROR(ROUND(Y33*$U33/$X33,5),"- -") -> - - | F33: =IFERROR(ROUND(AA33*$U33/$Z33,5),"- -") -> - - | G33: =IFERROR(ROUND(AVERAGE(D33:F33),5),"- -") -> - - | J33: =U33 -> 0 | K33: =IFERROR(ROUND((($M$17*D33+$M$18*D33^2+$M$19*D33^3)),3),"- -") -> - - | L33: =IFERROR(ROUND((($M$17*E33+$M$18*E33^2+$M$19*E33^3)),3),"- -") -> - - | M33: =IFERROR(ROUND((($M$17*F33+$M$18*F33^2+$M$19*F33^3)),3),"- -") -> - - | N33: =IFERROR(ROUND(AVERAGE(K33:M33),3),"- -") -> - - | T33: =IFERROR('Dash Board'!T17,"- -") -> 0 | U33: =T33*Software!$K$35 -> 0 | V33: =Software!F75 -> - - | W33: =Software!J75 -> - - | X33: =Software!F91 -> - - | Y33: =Software!J91 -> - - | Z33: =Software!F107 -> - - | AA33: =Software!J107 -> - - | AB33: =IFERROR(ROUND(AVERAGE(W33,Y33,AA33),5),"- -") -> - - | AC33: =N33 -> - - | AF33: =((100/N33)*(SQRT(((K33-N33)^2+(L33-N33)^2+(M33-N33)^2)/2)))/SQRT(3) -> #VALUE! | AG33: =($AE$24*100)/(N33*2*SQRT(3)) -> #VALUE! | AH33: =$AE$21/2 -> 0.0055 | AI33: =($AE$27*$AE$29)/SQRT(3) -> 0 | AJ33: =$AE$31/SQRT(3) -> 0.028867513 | AK33: =SQRT((SUMSQ(AH33:AJ33))) -> 0.029386788 | AL33: =SQRT(SUMSQ(AF33,AG33,AK33)) -> #VALUE! | AN33: 2 | AO33: =AN33*AL33 -> #VALUE! | AQ33: =IFERROR(((J33-N33)/N33)*100,"- -") -> - - | AR33: =IFERROR((MAX(K33,L33,M33)-MIN(K33,L33,M33))/N33*100,"- -") -> - - | AS33: =$V$36/IF($J$29<>0,$J$29,$J$29)*100 -> 0 | AU33: =IF(ABS(AQ33)<=0.5,0.5,IF(ABS(AQ33)<=1,1,IF(ABS(AQ33)<=2,2,IF(ABS(AQ33)<=3,3,"-")))) -> #VALUE! | AV33: =IF(AR33<=0.5,0.5,IF(AR33<=1,1,IF(AR33<=2,2,IF(AR33<=3,3,"-")))) -> - | AW33: =IF(ABS(AS33)<=0.05,0.5,IF(ABS(AS33)<=0.1,1,IF(ABS(AS33)<=0.2,2,IF(ABS(AS33)<=0.3,3,"-")))) -> 0.5 | AX33: =IF($AX$18>=400,0.5,IF($AX$18>=200,1,IF($AX$18>=100,2,IF($AX$18>=67,3,"-")))) -> #DIV/0! | AY33: =IF($AE$21<=0.12,0.5,IF($AE$21<=0.25,1,IF($AE$21<=0.5,2,"-"))) -> 0.5 | AZ33: =MAX(AU33,AV33,AW33,AY33) -> #VALUE!
C34: =U34 -> 0 | D34: =IFERROR(ROUND(W34*$U34/$V34,5),"- -") -> - - | E34: =IFERROR(ROUND(Y34*$U34/$X34,5),"- -") -> - - | F34: =IFERROR(ROUND(AA34*$U34/$Z34,5),"- -") -> - - | G34: =IFERROR(ROUND(AVERAGE(D34:F34),5),"- -") -> - - | J34: =U34 -> 0 | K34: =IFERROR(ROUND((($M$17*D34+$M$18*D34^2+$M$19*D34^3)),3),"- -") -> - - | L34: =IFERROR(ROUND((($M$17*E34+$M$18*E34^2+$M$19*E34^3)),3),"- -") -> - - | M34: =IFERROR(ROUND((($M$17*F34+$M$18*F34^2+$M$19*F34^3)),3),"- -") -> - - | N34: =IFERROR(ROUND(AVERAGE(K34:M34),3),"- -") -> - - | T34: =IFERROR('Dash Board'!T18,"- -") -> 0 | U34: =T34*Software!$K$35 -> 0 | V34: =Software!F76 -> - - | W34: =Software!J76 -> - - | X34: =Software!F92 -> - - | Y34: =Software!J92 -> - - | Z34: =Software!F108 -> - - | AA34: =Software!J108 -> - - | AB34: =IFERROR(ROUND(AVERAGE(W34,Y34,AA34),5),"- -") -> - - | AC34: =N34 -> - - | AF34: =((100/N34)*(SQRT(((K34-N34)^2+(L34-N34)^2+(M34-N34)^2)/2)))/SQRT(3) -> #VALUE! | AG34: =($AE$24*100)/(N34*2*SQRT(3)) -> #VALUE! | AH34: =$AE$21/2 -> 0.0055 | AI34: =($AE$27*$AE$29)/SQRT(3) -> 0 | AJ34: =$AE$31/SQRT(3) -> 0.028867513 | AK34: =SQRT((SUMSQ(AH34:AJ34))) -> 0.029386788 | AL34: =SQRT(SUMSQ(AF34,AG34,AK34)) -> #VALUE! | AN34: 2 | AO34: =AN34*AL34 -> #VALUE! | AQ34: =IFERROR(((J34-N34)/N34)*100,"- -") -> - - | AR34: =IFERROR((MAX(K34,L34,M34)-MIN(K34,L34,M34))/N34*100,"- -") -> - - | AS34: =$V$36/IF($J$29<>0,$J$29,$J$29)*100 -> 0 | AU34: =IF(ABS(AQ34)<=0.5,0.5,IF(ABS(AQ34)<=1,1,IF(ABS(AQ34)<=2,2,IF(ABS(AQ34)<=3,3,"-")))) -> #VALUE! | AV34: =IF(AR34<=0.5,0.5,IF(AR34<=1,1,IF(AR34<=2,2,IF(AR34<=3,3,"-")))) -> - | AW34: =IF(ABS(AS34)<=0.05,0.5,IF(ABS(AS34)<=0.1,1,IF(ABS(AS34)<=0.2,2,IF(ABS(AS34)<=0.3,3,"-")))) -> 0.5 | AX34: =IF($AX$18>=400,0.5,IF($AX$18>=200,1,IF($AX$18>=100,2,IF($AX$18>=67,3,"-")))) -> #DIV/0! | AY34: =IF($AE$21<=0.12,0.5,IF($AE$21<=0.25,1,IF($AE$21<=0.5,2,"-"))) -> 0.5 | AZ34: =MAX(AU34,AV34,AW34,AY34) -> #VALUE!
C35: 0 | D35: 0 | E35: 0 | F35: 0 | G35: =ROUND((M17*Z24+M18*Z24^2)*1000,0) -> 0 | J35: =U35 -> 0 | K35: 0 | L35: =ROUND((($M$17*E35+$M$18*E35^2+$M$19*E35^3)),3) -> 0 | M35: =ROUND((($M$17*F35+$M$18*F35^2+$M$19*F35^3)),3) -> 0 | N35: 0 | T35: =IFERROR('Dash Board'!T19,"- -") -> 0 | U35: =T35*Software!$K$35 -> 0 | V35: =Software!F77 -> 0 | W35: =Software!J77 -> -0.000642 | X35: =Software!F93 -> 0 | Y35: =Software!J93 -> -0.000642 | Z35: =Software!F109 -> 0 | AA35: =Software!J109 -> -0.000642 | AB35: =ROUND(AVERAGE(W35,Y35,AA35),5) -> -0.00064 | AC35: =N35 -> 0
T36: Max Zero | U36: = | V36: =MAX(V35,X35,Z35) -> 0
AF37: =(STDEV(K25:M25)/SQRT(3))/1 -> 1.0048592e-14

Sheet Load Cell db
B3: Description | C3: Capacity | D3: Serial Number | E3: Calibration Certificate | F3: Calibration Date | G3: a' (Compression) | H3: b' (Compression) | I3: c' (Compression) | J3: U (Compression) | K3: a' (Tension) | L3: b' (Tension) | M3: c' (Tension) | N3: U (Tension) | O3: Next Cal Date
B4: HBM/C6 | C4: 2000 kN | D4: F42442 | E4: 1800-00040-002 | F4: 43153 | G4: 978.3389 | H4: 35.04818 | I4: -7.94019 | J4: 1.375 | K4: -- | L4: -- | M4: -- | N4: -- | O4: =DATE(YEAR(Table1[[#This Row],[Calibration Date]])+3, MONTH(Table1[[#This Row],[Calibration Date]]),DAY(Table1[[#This Row],[Calibration Date]])) -> 44249
B5: HBM/TCBS | C5: 500 kN | D5: 50036 | E5: 1800-00040-003 | F5: 43161 | G5: -247.8101 | H5: 0.4774382 | I5: -0.01014075 | J5: 0.07 | K5: -- | L5: -- | M5: -- | N5: -- | O5: =DATE(YEAR(Table1[[#This Row],[Calibration Date]])+3, MONTH(Table1[[#This Row],[Calibration Date]]),DAY(Table1[[#This Row],[Calibration Date]])) -> 44257
B6: HBM/C3H3 | C6: 10 kN | D6: F93007 | E6: 1800-00040-004 | F6: 43161 | G6: 4.902632 | H6: -0.0009307508 | I6: -6.355071e-05 | J6: 0.011 | K6: -4.902262 | L6: 0.0004106273 | M6: -0.0001682559 | N6: 0.012 | O6: =DATE(YEAR(Table1[[#This Row],[Calibration Date]])+3, MONTH(Table1[[#This Row],[Calibration Date]]),DAY(Table1[[#This Row],[Calibration Date]])) -> 44257
B7: HBM/Z3H3 | C7: 5 kN | D7: F73724 | E7: 1800-00040-005 | F7: 43161 | G7: 2.449533 | H7: 0.0003271097 | I7: -0.000173873 | J7: 0.017 | K7: -2.450352 | L7: -0.0003149063 | M7: -9.935562e-05 | N7: 0.019 | O7: =DATE(YEAR(Table1[[#This Row],[Calibration Date]])+3, MONTH(Table1[[#This Row],[Calibration Date]]),DAY(Table1[[#This Row],[Calibration Date]])) -> 44257
B8: HBM/Z3OA | C8: 2 kN | D8: 151730166 | E8: 1600-02019-001 | F8: 42538 | G8: 1000.037 | H8: -0.0910095 | I8: -0.001796771 | J8: 0.024 | K8: -- | L8: -- | M8: -- | N8: -- | O8: =DATE(YEAR(Table1[[#This Row],[Calibration Date]])+3, MONTH(Table1[[#This Row],[Calibration Date]]),DAY(Table1[[#This Row],[Calibration Date]])) -> 43633
B9: HBM/Z4A (20kN) | C9: 20 kN | D9: 161430192 | E9: 1600-02019-003 | F9: 42545 | G9: 10.00259 | H9: 0.0007285711 | I9: -0.0005834712 | J9: 0.019 | K9: -10.00219 | L9: 0.001893269 | M9: 0.0004154442 | N9: 0.012 | O9: =DATE(YEAR(Table1[[#This Row],[Calibration Date]])+3, MONTH(Table1[[#This Row],[Calibration Date]]),DAY(Table1[[#This Row],[Calibration Date]])) -> 43640
B10: HBM/Z4A (100kN) | C10: 100 kN | D10: 160730020 | E10: 1600-02019-002 | F10: 42580 | G10: 50.03392 | H10: -0.01476225 | I10: -0.002207862 | J10: 0.041 | K10: -50.03464 | L10: 0.006267658 | M10: 0.002665654 | N10: 0.053 | O10: =DATE(YEAR(Table1[[#This Row],[Calibration Date]])+3, MONTH(Table1[[#This Row],[Calibration Date]]),DAY(Table1[[#This Row],[Calibration Date]])) -> 43675
B11: WBRC/R200K | C11: 200 kN | D11: WB-1210-010 | E11: 1600-02019-004 | F11: 42576 | G11: 90.78289 | H11: -0.03282234 | I11: -0.004875593 | J11: 0.081 | K11: -- | L11: -- | M11: -- | N11: -- | O11: =DATE(YEAR(Table1[[#This Row],[Calibration Date]])+3, MONTH(Table1[[#This Row],[Calibration Date]]),DAY(Table1[[#This Row],[Calibration Date]])) -> 43671
B12: WBRC-R2M | C12: 2 MN | D12: WB-121005 | E12: 1800-00040-001 | F12: 43153 | G12: 1379.299 | H12: 24.79271 | I12: 18.28049 | J12: 0.078 | K12: -- | L12: -- | M12: -- | N12: -- | O12: =DATE(YEAR(Table1[[#This Row],[Calibration Date]])+3, MONTH(Table1[[#This Row],[Calibration Date]]),DAY(Table1[[#This Row],[Calibration Date]])) -> 44249
B13: Shimadzu/ UH-F1000kNX | C13: 1000 kN | D13: 1251056K0094 | E13: 11-2020-FORC-0116 | F13: 44138 | J13: 0.23 | K13: -- | L13: -- | M13: -- | N13: 0.1 | O13: =DATE(YEAR(Table1[[#This Row],[Calibration Date]])+3, MONTH(Table1[[#This Row],[Calibration Date]]),DAY(Table1[[#This Row],[Calibration Date]])) -> 45233

Sheet Data
B1: CALIBRATION DATA SHEET
B2: Customer Name: | D2: - -
B3: Address Line 1: | D3: - -
B4: Address Line 2: | D4: - -
B5: Date of Calibration: | D5: - - | J5: Mode: | K5: Compression
B6: Request Ref. No.: | D6: Dynamic Unit Test Conv | J6: Capacity: | K6: 100 tf
B7: Calibration Item: | D7: - - | J7: Range: | K7: - -
B8: Load Cell
B9: Make / Model No.: | D9: - - | J9: Increment: | K9: - -
B10: Serial No. / ID No.: | D10: - - | J10: Resolution: | K10: - -
B11: Indicator
B12: Make / Model No.: | D12: - - | K12: ='Dash Board'!N25 &" "& 'Dash Board'!O26
B13: Serial No. / ID No.: | D13: - - | K13: ='Dash Board'!N26 &" "& 'Dash Board'!O26
B15: 2.) PRE-LOADING DATA, tf
B17: Indicated force | C17: 1st (0˚) | D17: Indicated force | F17: 2nd (120˚) | G17: Indicated force | H17: 3rd (240˚) | J17: Conversion Unit:
B18: =Software!E45 -> 0 | C18: 0 | D18: =Software!E52 -> 0 | G18: =Software!E59 -> 0 | J18: 1 tf = | K18: 9.80665 | L18: kN
B19: 15000 | C19: 14950 | D19: =B19 -> 15000 | G19: =B19 -> 15000
B20: =Software!E47 -> 0 | C20: 0 | D20: =Software!E54 -> 0 | G20: =Software!E61 -> 0
B22: 3.) MEASURED DATA, tf
C23: Target (tf) | K23: Mean Force (tf)
B24: Calibration Points | C24: Expected Machine Indication | D24: Indicated force | F24: 1st | G24: Indicated force | H24: 2nd | I24: Indicated force | J24: 3rd | K24: Mean Force | L24: Mean deflection
B25: 0 | C25: - - | D25: - - | F25: - - | G25: - - | H25: - - | I25: - - | J25: - - | K25: - - | L25: - -
B26: 1st | C26: - - | D26: - - | F26: - - | G26: - - | H26: - - | I26: - - | J26: - - | K26: - - | L26: - -
B27: 2nd | C27: - - | D27: - - | F27: - - | G27: - - | H27: - - | I27: - - | J27: - - | K27: - - | L27: - -
B28: 3rd | C28: - - | D28: - - | F28: - - | G28: - - | H28: - - | I28: - - | J28: - - | K28: - - | L28: - -
B29: 4th | C29: - - | D29: - - | F29: - - | G29: - - | H29: - - | I29: - - | J29: - - | K29: - - | L29: - -
B30: 5th | C30: - - | D30: - - | F30: - - | G30: - - | H30: - - | I30: - - | J30: - - | K30: - - | L30: - -
B31: 6th | C31: - - | D31: - - | F31: - - | G31: - - | H31: - - | I31: - - | J31: - - | K31: - - | L31: - -
B32: 7th | C32: - - | D32: - - | F32: - - | G32: - - | H32: - - | I32: - - | J32: - - | K32: - - | L32: - -
B33: 8th | C33: - - | D33: - - | F33: - - | G33: - - | H33: - - | I33: - - | J33: - - | K33: - - | L33: - -
B34: 9th | C34: - - | D34: - - | F34: - - | G34: - - | H34: - - | I34: - - | J34: - - | K34: - - | L34: - -
B35: 10th | C35: - - | D35: - - | F35: - - | G35: - - | H35: - - | I35: - - | J35: - - | K35: - - | L35: - -
B36: 0 | C36: =IF('Dash Board'!T19<>"",'Dash Board'!T19,"- -") -> 0 | D36: =C36 -> 0 | F36: 0 | G36: =IF(C36="- -","",C36) -> 0 | H36: 0 | I36: =IF(C36="- -","",C36) -> 0 | J36: 0
B37: Max Zero =
B39: 3.) Force Transducer Information | J39: 4.) Environmental Conditions:
B41: ="In: "&K5&" Mode" -> In: Compression Mode | J41: Thermo-hygrometer indication
B42: Load Cell | C42: - - | E42: =IF('Dash Board'!$N$17="Compression",6,10) -> 6 | F42: A | G42: - - | H42: equalsVLOOKUP($E$36,Table1,H36,FALSE) | K42: Before | L42: After
B43: Capacity | C43: =VLOOKUP($C$42,Table1[],2,FALSE) -> #N/A | E43: =IF('Dash Board'!$N$17="Compression",7,11) -> 7 | F43: B | G43: - - | H43: equalsVLOOKUP($E$36,Table1,H37,FALSE) | J43: Temp: | K43: - - | L43: - -
B44: Serial No. | C44: - - | E44: =IF('Dash Board'!$N$17="Compression",8,12) -> 8 | F44: C | G44: - - | H44: equalsVLOOKUP($E$36,Table1,H38,FALSE) | J44: Humidity: | K44: - - | L44: - -
B45: Cal. Cert. No. | C45: - - | E45: =IF('Dash Board'!$N$17="Compression",9,13) -> 9 | F45: U, % | G45: - - | H45: equalsVLOOKUP($E$36,Table1,H39,FALSE)
...

Sheet Certificate 10PTS
A6: CALIBRATION CERTIFICATE
A7: ="No. "&'Dash Board'!D18 -> No. 03-2026-FORC-0087
A9: Date of Calibration | G9: : | H9: ='Dash Board'!D17 -> 46134
A10: Calibration Item | G10: : | H10: ='Dash Board'!D19 -> Axle Weighing Scale
B11: Capacity | G11: : | H11: ='Calibration Data'!L10 -> 15000 kgf
B12: Measurement Range | G12: : | H12: ='Calibration Data'!L11 -> 0 kgf to 15000 kgf
B13: ='Dash Board'!K21 -> Resolution : | G13: : | H13: ='Calibration Data'!L12 -> 50
B14: Make / Model | G14: : | H14: ='Calibration Data'!C11 -> LS 630 W. PAD
B15: Serial No. | G15: : | H15: ='Calibration Data'!C12 -> 0122YL21002
H16: =Software!O21& " (Indicator)" -> (Indicator)
A17: Customer | G17: : | H17: =UPPER('Calibration Data'!C7) -> SAVVICE CORPORATION
H18: ='Dash Board'!D8 -> 3rd Floor BMWC Bldg., Cagayan Valley Road
H19: =IF('Dash Board'!D9<>0,'Dash Board'!D9,"") -> Sta. Rita, Guiginto, Bulacan
A21: MEASUREMENT RESULTS:
A23: Refer to the "Calibration Results" on the next page(s).
A25: UNCERTAINTY OF MEASUREMENT:
A27: The uncertainty stated is the expanded uncertainty obtained by multiplying the standard uncertainty by the coverage factor k = 2. It has been determined in accordance with the “JCGM 100:2008 Evaluation of measurement data- Guide to the Expression of Uncertainty in measurement ”. The value of the measurand lies within the assigned range of values with a probability of approximately 95%.
A29: STANDARD USED :
A31: Name of Standard | G31: Make/Model | J31: Calibration Certificate No. | M31: Traceability
A32: ="Load Cell SN "&Software!E38 -> Load Cell SN F93007 | G32: =IFERROR(LEFT(Software!E36,8),Software!E36) -> HBM/C3H3 | J32: =Software!E39 -> 1800-00040-004 | M32: Traceable to SI through KRISS - Korea
A34: CALIBRATION PROCEDURE:
A36: The testing machine under calibration was subjected to specified force values which were applied on the force-proving instrument and readings were noted.
A38: The relevant method for this calibration is ISO 7500-1:2018, Metallic materials – Verification of static uniaxial testing machines.
A40: ENVIRONMENTAL CONDITIONS:
B42: Ambient Temperature | H42: =" : ("&ROUND('Calibration Data'!P19,1)&"± 1) °C" -> : (25± 1) °C
B43: Relative Humidity | H43: =" : ("&ROUND('Calibration Data'!Q19,1)&"± 5)" -> : (33± 5)
A45: Page 1 of 2
A47: CALIBRATION RESULTS
A48: Compression
A49: Indicated Force | G49: Applied Force | I49: Relative Expanded Uncertainty | K49: Relative Accuracy Error | L49: Relative Repeatability Error | O49: Class
A50: =Software!E21 -> kgf | D50: kN | G50: kN | I50: % | K50: % | L50: %
A51: ='Calibration Data'!T24 -> 0 | D51: ='Calibration Data'!U24 -> 0 | G51: ='Calibration Data'!N24 -> 0 | I51: 0 | K51: 0 | L51: 0 | O51: ='Calibration Data'!AZ24 -> -
A52: ='Calibration Data'!T25 -> 3000 | D52: ='Calibration Data'!U25 -> 29.41995 | G52: ='Calibration Data'!N25 -> 118.1 | I52: =ROUNDUP('Calibration Data'!AO26,2) -> 0.06 | K52: =ROUNDUP('Calibration Data'!AQ26,2) -> -74.53 | L52: =ROUNDUP('Calibration Data'!AR25,2) -> 0 | O52: ='Calibration Data'!AZ25 -> 0.5
A53: ='Calibration Data'!T26 -> 6000 | D53: ='Calibration Data'!U26 -> 58.8399 | G53: ='Calibration Data'!N26 -> 230.967 | I53: =ROUNDUP('Calibration Data'!AO27,2) -> 0.06 | K53: =ROUNDUP('Calibration Data'!AQ27,2) -> -73.66 | L53: =ROUNDUP('Calibration Data'!AR26,2) -> 0 | O53: ='Calibration Data'!AZ26 -> 0.5
A54: ='Calibration Data'!T27 -> 9000 | D54: ='Calibration Data'!U27 -> 88.25985 | G54: ='Calibration Data'!N27 -> 335.023 | I54: =ROUNDUP('Calibration Data'!AO28,2) -> 0.06 | K54: =ROUNDUP('Calibration Data'!AQ28,2) -> -72.24 | L54: =ROUNDUP('Calibration Data'!AR27,2) -> 0 | O54: ='Calibration Data'!AZ27 -> 0.5
A55: ='Calibration Data'!T28 -> 12000 | D55: ='Calibration Data'!U28 -> 117.6798 | G55: ='Calibration Data'!N28 -> 423.778 | I55: =ROUNDUP('Calibration Data'!AO29,2) -> 0.06 | K55: =ROUNDUP('Calibration Data'!AQ29,2) -> -70.14 | L55: =ROUNDUP('Calibration Data'!AR28,2) -> 0 | O55: ='Calibration Data'!AZ28 -> 0.5
A56: ='Calibration Data'!T29 -> 15000 | D56: ='Calibration Data'!U29 -> 147.09975 | G56: ='Calibration Data'!N29 -> 492.512 | I56: =ROUNDUP('Calibration Data'!AO30,2) -> #VALUE! | K56: =ROUNDUP('Calibration Data'!AQ30,2) -> #VALUE! | L56: =ROUNDUP('Calibration Data'!AR29,2) -> 0 | O56: ='Calibration Data'!AZ29 -> 0.5
A57: ='Calibration Data'!T30 -> 0 | D57: ='Calibration Data'!U30 -> 0 | G57: ='Calibration Data'!N30 -> - - | I57: =ROUNDUP('Calibration Data'!AO31,2) -> #VALUE! | K57: =ROUNDUP('Calibration Data'!AQ31,2) -> #VALUE! | L57: =ROUNDUP('Calibration Data'!AR30,2) -> #VALUE! | O57: ='Calibration Data'!AZ30 -> #VALUE!
A58: ='Calibration Data'!T31 -> 0 | D58: ='Calibration Data'!U31 -> 0 | G58: ='Calibration Data'!N31 -> - - | I58: =ROUNDUP('Calibration Data'!AO32,2) -> #VALUE! | K58: =ROUNDUP('Calibration Data'!AQ32,2) -> #VALUE! | L58: =ROUNDUP('Calibration Data'!AR31,2) -> #VALUE! | O58: ='Calibration Data'!AZ31 -> #VALUE!
A59: ='Calibration Data'!T32 -> 0 | D59: ='Calibration Data'!U32 -> 0 | G59: ='Calibration Data'!N32 -> - - | I59: =ROUNDUP('Calibration Data'!AO33,2) -> #VALUE! | K59: =ROUNDUP('Calibration Data'!AQ33,2) -> #VALUE! | L59: =ROUNDUP('Calibration Data'!AR32,2) -> #VALUE! | O59: ='Calibration Data'!AZ32 -> #VALUE!
...

Sheet Certificate 10 pts
A6: CALIBRATION CERTIFICATE
A7: ="No. "&'Dash Board'!D18 -> No. 03-2026-FORC-0087
A9: Date of Calibration | G9: : | H9: ='Dash Board'!D17 -> 46134
A10: Calibration Item | G10: : | H10: ='Dash Board'!D19 -> Axle Weighing Scale
B11: Capacity | G11: : | H11: ='Calibration Data'!L10 -> 15000 kgf
B12: Measurement Range | G12: : | H12: ='Calibration Data'!L11 -> 0 kgf to 15000 kgf
B13: ='Dash Board'!K21 -> Resolution : | G13: : | H13: ='Calibration Data'!L12 -> 50
B14: Make / Model | G14: : | H14: ='Calibration Data'!C11&" (Load Cell); "&IF('Dash Board'!D26<>"",'Dash Board'!D26&" (Indicator)","") -> LS 630 W. PAD (Load Cell); INTERCOMP PT20 (Indicator)
B15: Serial No. | G15: : | H15: ='Calibration Data'!C12&" (Load Cell); "&IF('Dash Board'!D27<>"",'Dash Board'!D27&" (Indicator)","") -> 0122YL21002 (Load Cell); 0307YM23003 (Indicator)
H16: =Software!O21& " (Indicator)" -> (Indicator)
A17: Customer | G17: : | H17: =UPPER('Calibration Data'!C7) -> SAVVICE CORPORATION
H18: ='Dash Board'!D8 -> 3rd Floor BMWC Bldg., Cagayan Valley Road
H19: =IF('Dash Board'!D9<>0,'Dash Board'!D9,"") -> Sta. Rita, Guiginto, Bulacan
A21: MEASUREMENT RESULTS:
A23: Indicated Force | G23: Applied Force | I23: Relative Expanded Uncertainty | K23: Relative Accuracy Error | L23: Relative Repeatability Error | O23: Class
A24: =Software!E21 -> kgf | D24: kN | G24: kN | I24: % | K24: % | L24: %
A25: ='Calibration Data'!T24 -> 0 | D25: ='Calibration Data'!U24 -> 0 | G25: ='Calibration Data'!N24 -> 0 | I25: 0 | K25: 0 | L25: 0 | O25: ='Calibration Data'!AZ24 -> -
A26: ='Calibration Data'!T25 -> 3000 | D26: ='Calibration Data'!U25 -> 29.41995 | G26: ='Calibration Data'!N25 -> 118.1 | I26: =ROUNDUP('Calibration Data'!AO25,2) -> 0.06 | K26: =ROUNDUP('Calibration Data'!AQ25,2) -> -75.09 | L26: =ROUNDUP('Calibration Data'!AR25,2) -> 0 | O26: ='Calibration Data'!AZ25 -> 0.5
A27: ='Calibration Data'!T26 -> 6000 | D27: ='Calibration Data'!U26 -> 58.8399 | G27: ='Calibration Data'!N26 -> 230.967 | I27: =ROUNDUP('Calibration Data'!AO26,2) -> 0.06 | K27: =ROUNDUP('Calibration Data'!AQ26,2) -> -74.53 | L27: =ROUNDUP('Calibration Data'!AR26,2) -> 0 | O27: ='Calibration Data'!AZ26 -> 0.5
A28: ='Calibration Data'!T27 -> 9000 | D28: ='Calibration Data'!U27 -> 88.25985 | G28: ='Calibration Data'!N27 -> 335.023 | I28: =ROUNDUP('Calibration Data'!AO27,2) -> 0.06 | K28: =ROUNDUP('Calibration Data'!AQ27,2) -> -73.66 | L28: =ROUNDUP('Calibration Data'!AR27,2) -> 0 | O28: ='Calibration Data'!AZ27 -> 0.5
A29: ='Calibration Data'!T28 -> 12000 | D29: ='Calibration Data'!U28 -> 117.6798 | G29: ='Calibration Data'!N28 -> 423.778 | I29: =ROUNDUP('Calibration Data'!AO28,2) -> 0.06 | K29: =ROUNDUP('Calibration Data'!AQ28,2) -> -72.24 | L29: =ROUNDUP('Calibration Data'!AR28,2) -> 0 | O29: ='Calibration Data'!AZ28 -> 0.5
A30: ='Calibration Data'!T29 -> 15000 | D30: ='Calibration Data'!U29 -> 147.09975 | G30: ='Calibration Data'!N29 -> 492.512 | I30: =ROUNDUP('Calibration Data'!AO29,2) -> 0.06 | K30: =ROUNDUP('Calibration Data'!AQ29,2) -> -70.14 | L30: =ROUNDUP('Calibration Data'!AR29,2) -> 0 | O30: ='Calibration Data'!AZ29 -> 0.5
A31: ='Calibration Data'!T30 -> 0 | D31: ='Calibration Data'!U30 -> 0 | G31: ='Calibration Data'!N30 -> - - | I31: 0 | K31: 0 | L31: 0 | O31: ='Calibration Data'!AZ30 -> #VALUE!
A32: ='Calibration Data'!T31 -> 0 | D32: ='Calibration Data'!U31 -> 0 | G32: ='Calibration Data'!N31 -> - - | I32: =ROUNDUP('Calibration Data'!AO31,2) -> #VALUE! | K32: =ROUNDUP('Calibration Data'!AQ31,2) -> #VALUE! | L32: =ROUNDUP('Calibration Data'!AR31,2) -> #VALUE! | O32: ='Calibration Data'!AZ31 -> #VALUE!
A33: ='Calibration Data'!T32 -> 0 | D33: ='Calibration Data'!U32 -> 0 | G33: ='Calibration Data'!N32 -> - - | I33: =ROUNDUP('Calibration Data'!AO32,2) -> #VALUE! | K33: =ROUNDUP('Calibration Data'!AQ32,2) -> #VALUE! | L33: =ROUNDUP('Calibration Data'!AR32,2) -> #VALUE! | O33: ='Calibration Data'!AZ32 -> #VALUE!
A34: ='Calibration Data'!T33 -> 0 | D34: ='Calibration Data'!U33 -> 0 | G34: ='Calibration Data'!N33 -> - - | I34: =ROUNDUP('Calibration Data'!AO33,2) -> #VALUE! | K34: =ROUNDUP('Calibration Data'!AQ33,2) -> #VALUE! | L34: =ROUNDUP('Calibration Data'!AR33,2) -> #VALUE! | O34: ='Calibration Data'!AZ33 -> #VALUE!
A35: ='Calibration Data'!T34 -> 0 | D35: ='Calibration Data'!U34 -> 0 | G35: ='Calibration Data'!N34 -> - - | I35: =ROUNDUP('Calibration Data'!AO34,2) -> #VALUE! | K35: =ROUNDUP('Calibration Data'!AQ34,2) -> #VALUE! | L35: =ROUNDUP('Calibration Data'!AR34,2) -> #VALUE! | O35: ='Calibration Data'!AZ34 -> #VALUE!
A36: ='Calibration Data'!T35 -> 0 | D36: ='Calibration Data'!U35 -> 0 | G36: ='Calibration Data'!N35 -> 0 | I36: =ROUNDUP('Calibration Data'!AO35,2) -> 0 | K36: =ROUNDUP('Calibration Data'!AQ35,2) -> 0 | L36: =ROUNDUP('Calibration Data'!AR35,2) -> 0 | O36: ='Calibration Data'!AZ35 -> 0
A38: UNCERTAINTY OF MEASUREMENT:
A40: The uncertainty stated is the expanded uncertainty obtained by multiplying the standard uncertainty by the coverage factor k = 2. It has been determined in accordance with the “JCGM 100:2008 Evaluation of measurement data- Guide to the Expression of Uncertainty in measurement ”. The value of the measurand lies within the assigned range of values with a probability of approximately 95%.
A43: Page 1 of 2
A45: STANDARD USED :
A47: Name of Standard | G47: Make/Model | J47: Calibration Certificate No. | M47: Traceability
A48: ="Load Cell SN "&Software!E38 -> Load Cell SN F93007 | G48: =IFERROR(LEFT(Software!E36,8),Software!E36) -> HBM/C3H3 | J48: =Software!E39 -> 1800-00040-004 | M48: Traceable to SI through KRISS - Korea
A51: CALIBRATION PROCEDURE:
A53: The testing machine under calibration was subjected to specified force values which were applied on the force-proving instrument and readings were noted.
A55: The relevant reference document for this calibration is ISO 7500-1:2018, Metallic materials – Verification of static uniaxial testing machines.
A58: ENVIRONMENTAL CONDITIONS:
B60: Ambient Temperature | H60: =" : ("&ROUND('Calibration Data'!P19,1)&" ± 1) °C" -> : (25 ± 1) °C
B61: Relative Humidity | H61: =" : ("&ROUND('Calibration Data'!Q19,1)&" ± 5) % " -> : (33 ± 5) %
...

Sheet Certificate 5 pts (SI)
A6: CALIBRATION CERTIFICATE
A7: ="No. "&'Dash Board'!D18 -> No. 03-2026-FORC-0087
A9: Date of Calibration | G9: : | H9: ='Dash Board'!D17 -> 46134
A10: Calibration Item | G10: : | H10: ='Dash Board'!D19&IF('Dash Board'!D20<>""," ("&'Dash Board'!D20&")","") -> Axle Weighing Scale
B11: Capacity | G11: : | H11: =Data!K6 -> 100 tf
B12: Measurement Range | G12: : | H12: =Data!K7 -> - -
B13: ='Dash Board'!K21 -> Resolution : | G13: : | H13: =Data!K10 -> - -
B14: Make / Model | G14: : | H14: =IF('Dash Board'!D21="Yes",'Dash Board'!D23&" (Load Cell); "&'Dash Board'!D26&" (Indicator)",'Dash Board'!D23&"; "&'Dash Board'!D26&" ") -> LS 630 W. PAD; INTERCOMP PT20
B15: Serial No. | G15: : | H15: =IF('Dash Board'!D21="Yes",'Dash Board'!D24&" (Load Cell)"&'Dash Board'!D27&" (Indicator)",IF('Dash Board'!D26<>"",'Dash Board'!D24&"; "&'Dash Board'!D27&" (Indicator)",'Dash Board'!D24)) -> 0122YL21002; 0307YM23003 (Indicator)
H16: =Software!O21& " (Indicator)" -> (Indicator)
A17: Customer | G17: : | H17: =UPPER('Dash Board'!D7) -> SAVVICE CORPORATION
H18: ='Dash Board'!D8 -> 3rd Floor BMWC Bldg., Cagayan Valley Road
H19: =IF('Dash Board'!D9<>0,'Dash Board'!D9,"") -> Sta. Rita, Guiginto, Bulacan
A21: MEASUREMENT RESULTS:
C23: Applied Force (F std ) | G23: Indicated Force (F ind) | J23: Deviation (F ind - F std) | L23: Relative Expanded Uncertainty | P23: Relative Accuracy Error
C24: kgf | G24: kgf | J24: kgf | L24: % | P24: %
C25: 0 | G25: 0 | J25: 0 | L25: =Data!I89 -> - - | P25: =Data!J89 -> - -
C26: =Data!C26 -> - - | G26: =Data!L26 -> - - | J26: =G26-C26 -> #VALUE! | L26: =Data!I90 -> - - | P26: =Data!J90 -> - -
C27: =Data!C27 -> - - | G27: =Data!L27 -> - - | J27: =G27-C27 -> #VALUE! | L27: =Data!I91 -> - - | P27: =Data!J91 -> - -
C28: =Data!C28 -> - - | G28: =Data!L28 -> - - | J28: =G28-C28 -> #VALUE! | L28: =Data!I92 -> - - | P28: =Data!J92 -> - -
C29: =Data!C29 -> - - | G29: =Data!L29 -> - - | J29: =G29-C29 -> #VALUE! | L29: =Data!I93 -> - - | P29: =Data!J93 -> - -
C30: =Data!C30 -> - - | G30: =Data!L30 -> - - | J30: =G30-C30 -> #VALUE! | L30: =Data!I94 -> - - | P30: =Data!J94 -> - -
A33: UNCERTAINTY OF MEASUREMENT:
A35: The uncertainty stated is the expanded uncertainty obtained by multiplying the standard uncertainty by the coverage factor k = 2. It has been determined in accordance with the “JCGM 100:2008 Evaluation of measurement data- Guide to the expression of uncertainty in measurement”. The value of the measurand lies within the assigned range of values with a probability of approximately 95%.
A37: Page 1 of 2
A39: STANDARD USED :
A41: Name of Standard | H41: Make/Model | K41: Calibration Certificate No. | Q41: Traceability
A42: =IF('Dash Board'!D19="Axle Weighing Scale","Force Measuring Instrument SN "&Data!C44,"Load Cell SN "&Data!C44) -> Force Measuring Instrument SN - - | H42: =IFERROR(Data!C42,Software!E36) -> - - | K42: 02-2025-FORC-0072 | Q42: Traceable to the SI through NMD-ITDI
A45: CALIBRATION PROCEDURE:
A47: ="The "&LOWER('Dash Board'!D19)&" ("&LOWER('Dash Board'!D20)&") under calibration was subjected to specified force values which were applied on the working standard and readings were noted." -> The axle weighing scale () under calibration was subjected to specified force values which were applied on the working standard and readings were noted.
A49: The axle weighing scale was subjected to specified force values in comparison with force reference standard values. Three (3) series of increasing force values were applied to the axle weighing scale.
A51: The relevant references for this axle weighing scale calibration are the ISO 7500-1:2018 "Metallic materials-Calibration and verification of static uniaxial testing machine'' and TP-PFSS-F-FORC-02: (version 1) "Calibration of Axle Weighing Scales" .
A53: ENVIRONMENTAL CONDITIONS:
B55: Ambient Temperature | H55: =": ("&ROUND(AVERAGE(Data!K43:L43),0)&" ± 2) °C " -> #DIV/0!
B56: Relative Humidity | H56: =": ("&ROUND(AVERAGE(Data!K44:L44),0)&" ± 5) % " -> #DIV/0!
A58: REMARKS:
A60: - | B60: ="The above results were those obtained at the time of calibration and refer only to the axle weighing scale calibrated in static "&LOWER('Dash Board'!N17)&" mode." -> The above results were those obtained at the time of calibration and refer only to the axle weighing scale calibrated in static compression mode.
A62: - | B62: ="The overall performance of this "&LOWER('Dash Board'!D19)&" was "&IF(COUNTIFS(O26:R30,"-")>2,"UNSATISFACTORY.","SATISFACTORY.") -> The overall performance of this axle weighing scale was SATISFACTORY.
A63: - | B63: ="No adjustment was performed on the "&LOWER('Dash Board'!D19)&". The user should determine suitability of the "&LOWER('Dash Board'!D19)&" for its intended use." -> No adjustment was performed on the axle weighing scale. The user should determine suitability of the axle weighing scale for its intended use.
A64: - | B64: =IF('Dash Board'!O18="kN","The unit kN can only be directly converted to other force units.","The conversion factor is 1 "&'Dash Board'!O18&" = "&Data!K18&" kN.") -> The conversion factor is 1 kgf = 9.80665 kN.
...

Sheet Records
T6: Form No. F5.5.2
T7: Version 2 Page 1 of 1
A9: CALIBRATION RECORD
A10: (Use as first page of Data Sheet for any calibration or measurement work performed.)
A12: Request Reference No.: | J12: ='Dash Board'!$D$18 -> 03-2026-FORC-0087
A13: Instrument: | J13: ='Dash Board'!$D$19 -> Axle Weighing Scale
A14: Make / Model No. | J14: ='Dash Board'!$D$23 -> LS 630 W. PAD
A15: Customer: | J15: ='Dash Board'!$D$7 -> SAVVICE CORPORATION
A16: Environmental Conditions: | I16: ="("&ROUND(AVERAGE(Data!J43:K43),0)&" ± 2) °C" -> #DIV/0! | R16: ="("&ROUND(AVERAGE(Data!J44:K44),0)&" ± 5) % " -> #DIV/0!
A17: Calibration Procedure: | J17: ISO 7500/1
